Workbook

Sheet Parameters
A1: Simulation parameters
A2: Every number on Results comes from running the combat model 250 times per row.
A3: Blue cells are levers. Change one and the Results sheet formulas follow.
A5: Lever | B5: Value | C5: Source
A6: Seconds per action (full ceremony) | B6: 1.55 | C6: Measured from the animation prototype
A7: Seconds per action (quick mode) | B7: 0.72 | C7: Measured from the animation prototype
A8: Target session length (minutes) | B8: 47 | C8: From the pacing model
A9: Shield points per layer | B9: 14 | C9: SHPER in the build
A10: Damage soak while shielded | B10: 0.4 | C10: SOAK in the build
A11: Vulnerable bonus after break | B11: 0.35 | C11: BRK.vuln in the build
A12: Break delay (share of action value) | B12: 0.35 | C12: BRK.delay in the build
A13: Off-weakness shred rate | B13: 0.2 | C13: UNMATCHED in the build
A14: Round cap | B14: 18 | C14: Fight is lost if exceeded
A15: Seeds per row | B15: 250 | C15: Sample size behind each average

Sheet Matrix method
A1: How to run a team test
A3: 1 Calibrate the encounter first
A4: Move enemy health and damage until a plain team wins about two thirds and can lose both ways — wiped and timed out. A scenario where everything loses, or everything wins, measures nothing.
A7: 2 Score by breakpoint, not win rate
A8: Raise a single difficulty multiplier until the build drops below 75% wins. That number is comparable across builds; win rate at a fixed difficulty saturates and is not.
A11: 3 Sweep every scalar, never sample one
A12: A mechanic that looks dead at one value often has a threshold just above it. Ward read as worthless at 0.09 and reached 93% at 0.30.
A15: 4 Record how fights are lost
A16: Wiped and timed out call for opposite fixes. Collect both or you will tune the wrong side.
A19: 5 Score interest separately from power
A20: Power parity and watchability keep coming apart. A build can be equally strong and much duller. Both columns have to be read.
A23: 6 Vary the encounter as well as the team
... A27: Metrics
A28: metric | B28: what it measures | C28: kind
A29: breakpoint | B29: Difficulty multiplier where wins fall below 75%. Higher is stronger. | C29: power
A30: rounds | B30: Fight length in rounds at that breakpoint. | C30: pacing
A31: ev/rnd | B31: Damage events per round. Density of things happening. | C31: interest
A32: biggest | B32: Largest single number seen. The spectacle peak. | C32: interest
A33: escal | B33: Late-fight damage ÷ early-fight damage. Above 1.0 means the build comes online. | C33: interest
A34: even | B34: How evenly the crew contributes. 1.0 means everyone matters. | C34: interest
A35: drama | B35: How close results sit to a 75% win rate. 1.0 is maximum doubt. | C35: interest

Sheet Team matrix
A1: Team build matrix
A2: Each build tested against three encounter shapes. Breakpoint is the difficulty multiplier at which it stops winning three fights in four. 90 fights per probe, 150 at the breakpoint.
A4: build | B4: shape | C4: breakpoint | D4: win@bp | E4: rounds | F4: ev/rnd | G4: biggest | H4: dot | I4: heal | J4: follows | K4: even | L4: escal | M4: drama
A5: control plain damage | B5: reference | C5: 0.95 | D5: 78 | E5: 16.31 | F5: 8 | G5: 19 | H5: 0 | I5: 303 | J5: 0 | K5: 0.53 | L5: 0.48 | M5: 0.96
A6: control plain damage | B6: swarm | C6: 0.91 | D6: 94 | E6: 16.37 | F6: 9.1 | G6: 19 | H6: 0 | I6: 300 | J6: 0 | K6: 0.58 | L6: 0.58 | M6: 0.75
A7: control plain damage | B7: elite | C7: 1.61 | D7: 92.7 | E7: 15.73 | F7: 6 | G7: 27 | H7: 0 | I7: 257 | J7: 0 | K7: 0.59 | L7: 0.55 | M7: 0.76
A8: control all AoE | B8: reference | C8: 1.67 | D8: 80 | E8: 13.07 | F8: 18.8 | G8: 28 | H8: 0 | I8: 230 | J8: 0 | K8: 0.38 | L8: 0.28 | M8: 0.93
A9: control all AoE | B9: swarm | C9: 1.85 | D9: 73.3 | E9: 13.28 | F9: 22.5 | G9: 31 | H9: 0 | I9: 232 | J9: 0 | K9: 0.33 | L9: 0.4 | M9: 0.98
A10: control all AoE | B10: elite | C10: 2.13 | D10: 92 | E10: 14.26 | F10: 11.9 | G10: 36 | H10: 0 | I10: 239 | J10: 0 | K10: 0.51 | L10: 0.61 | M10: 0.77
A11: heavy dot 1 type big ticks | B11: reference | C11: 2 | D11: 73.3 | E11: 8.43 | F11: 18.1 | G11: 154 | H11: 1372 | I11: 207 | J11: 0 | K11: 0.33 | L11: 1.09 | M11: 0.98
A12: heavy dot 1 type big ticks | B12: swarm | C12: 1.91 | D12: 77.3 | E12: 10.56 | F12: 18.8 | G12: 154 | H12: 1412 | I12: 266 | J12: 0 | K12: 0.37 | L12: 0.54 | M12: 0.97
A13: heavy dot 1 type big ticks | B13: elite | C13: 2.92 | D13: 72.7 | E13: 9.73 | F13: 8.8 | G13: 154 | H13: 1280 | I13: 173 | J13: 0 | K13: 0.46 | L13: 0.91 | M13: 0.97
A14: heavy dot no support | B14: reference | C14: 1.72 | D14: 73.3 | E14: 7.65 | F14: 17.2 | G14: 154 | H14: 1144 | I14: 105 | J14: 0 | K14: 0.38 | L14: 1 | M14: 0.98
A15: heavy dot no support | B15: swarm | C15: 1.72 | D15: 77.3 | E15: 9.15 | F15: 18.2 | G15: 154 | H15: 1269 | I15: 147 | J15: 0 | K15: 0.4 | L15: 0.75 | M15: 0.97
A16: heavy dot no support | B16: elite | C16: 2.63 | D16: 76.7 | E16: 9.47 | F16: 8.6 | G16: 154 | H16: 1152 | I16: 131 | J16: 0 | K16: 0.46 | L16: 0.94 | M16: 0.98
... A46: hybrid dots + detonator | B46: elite | C46: 2.2 | D46: 80.7 | E46: 12.39 | F46: 9 | G46: 145 | H46: 872 | I46: 270 | J46: 0 | K46: 0.31 | L46: 0.39 | M46: 0.92
A49: A Breakpoint by encounter shape
A50: Higher is stronger. Compare down a column.
B51: reference | C51: swarm | D51: elite
A52: control plain damage | B52: =IFERROR(SUMIFS('Team matrix'!$C$5:$C$46,'Team matrix'!$A$5:$A$46,"control plain damage",'Team matrix'!$B$5:$B$46,"reference"),"") -> 0.95 | C52: =IFERROR(SUMIFS('Team matrix'!$C$5:$C$46,'Team matrix'!$A$5:$A$46,"control plain damage",'Team matrix'!$B$5:$B$46,"swarm"),"") -> 0.91 | D52: =IFERROR(SUMIFS('Team matrix'!$C$5:$C$46,'Team matrix'!$A$5:$A$46,"control plain damage",'Team matrix'!$B$5:$B$46,"elite"),"") -> 1.61
A53: control all AoE | B53: =IFERROR(SUMIFS('Team matrix'!$C$5:$C$46,'Team matrix'!$A$5:$A$46,"control all AoE",'Team matrix'!$B$5:$B$46,"reference"),"") -> 1.67 | C53: =IFERROR(SUMIFS('Team matrix'!$C$5:$C$46,'Team matrix'!$A$5:$A$46,"control all AoE",'Team matrix'!$B$5:$B$46,"swarm"),"") -> 1.85 | D53: =IFERROR(SUMIFS('Team matrix'!$C$5:$C$46,'Team matrix'!$A$5:$A$46,"control all AoE",'Team matrix'!$B$5:$B$46,"elite"),"") -> 2.13
A54: heavy dot 1 type big ticks | B54: =IFERROR(SUMIFS('Team matrix'!$C$5:$C$46,'Team matrix'!$A$5:$A$46,"heavy dot 1 type big ticks",'Team matrix'!$B$5:$B$46,"reference"),"") -> 2 | C54: =IFERROR(SUMIFS('Team matrix'!$C$5:$C$46,'Team matrix'!$A$5:$A$46,"heavy dot 1 type big ticks",'Team matrix'!$B$5:$B$46,"swarm"),"") -> 1.91 | D54: =IFERROR(SUMIFS('Team matrix'!$C$5:$C$46,'Team matrix'!$A$5:$A$46,"heavy dot 1 type big ticks",'Team matrix'!$B$5:$B$46,"elite"),"") -> 2.92
A55: heavy dot no support | B55: =IFERROR(SUMIFS('Team matrix'!$C$5:$C$46,'Team matrix'!$A$5:$A$46,"heavy dot no support",'Team matrix'!$B$5:$B$46,"reference"),"") -> 1.72 | C55: =IFERROR(SUMIFS('Team matrix'!$C$5:$C$46,'Team matrix'!$A$5:$A$46,"heavy dot no support",'Team matrix'!$B$5:$B$46,"swarm"),"") -> 1.72 | D55: =IFERROR(SUMIFS('Team matrix'!$C$5:$C$46,'Team matrix'!$A$5:$A$46,"heavy dot no support",'Team matrix'!$B$5:$B$46,"elite"),"") -> 2.63
A56: wide dot 4 types many hits | B56: =IFERROR(SUMIFS('Team matrix'!$C$5:$C$46,'Team matrix'!$A$5:$A$46,"wide dot 4 types many hits",'Team matrix'!$B$5:$B$46,"reference"),"") -> 1.54 | C56: =IFERROR(SUMIFS('Team matrix'!$C$5:$C$46,'Team matrix'!$A$5:$A$46,"wide dot 4 types many hits",'Team matrix'!$B$5:$B$46,"swarm"),"") -> 1.43 | D56: =IFERROR(SUMIFS('Team matrix'!$C$5:$C$46,'Team matrix'!$A$5:$A$46,"wide dot 4 types many hits",'Team matrix'!$B$5:$B$46,"elite"),"") -> 2.26
A57: wide dot 4 types no support | B57: =IFERROR(SUMIFS('Team matrix'!$C$5:$C$46,'Team matrix'!$A$5:$A$46,"wide dot 4 types no support",'Team matrix'!$B$5:$B$46,"reference"),"") -> 1.37 | C57: =IFERROR(SUMIFS('Team matrix'!$C$5:$C$46,'Team matrix'!$A$5:$A$46,"wide dot 4 types no support",'Team matrix'!$B$5:$B$46,"swarm"),"") -> 1.26 | D57: =IFERROR(SUMIFS('Team matrix'!$C$5:$C$46,'Team matrix'!$A$5:$A$46,"wide dot 4 types no support",'Team matrix'!$B$5:$B$46,"elite"),"") -> 2.07
A58: detonator stacks then burst | B58: =IFERROR(SUMIFS('Team matrix'!$C$5:$C$46,'Team matrix'!$A$5:$A$46,"detonator stacks then burst",'Team matrix'!$B$5:$B$46,"reference"),"") -> 1.5 | C58: =IFERROR(SUMIFS('Team matrix'!$C$5:$C$46,'Team matrix'!$A$5:$A$46,"detonator stacks then burst",'Team matrix'!$B$5:$B$46,"swarm"),"") -> 1.43 | D58: =IFERROR(SUMIFS('Team matrix'!$C$5:$C$46,'Team matrix'!$A$5:$A$46,"detonator stacks then burst",'Team matrix'!$B$5:$B$46,"elite"),"") -> 2.13
A59: chain follow-up cascade | B59: =IFERROR(SUMIFS('Team matrix'!$C$5:$C$46,'Team matrix'!$A$5:$A$46,"chain follow-up cascade",'Team matrix'!$B$5:$B$46,"reference"),"") -> 1.54 | C59: =IFERROR(SUMIFS('Team matrix'!$C$5:$C$46,'Team matrix'!$A$5:$A$46,"chain follow-up cascade",'Team matrix'!$B$5:$B$46,"swarm"),"") -> 1.5 | D59: =IFERROR(SUMIFS('Team matrix'!$C$5:$C$46,'Team matrix'!$A$5:$A$46,"chain follow-up cascade",'Team matrix'!$B$5:$B$46,"elite"),"") -> 2.66
A60: chain cascade same target | B60: =IFERROR(SUMIFS('Team matrix'!$C$5:$C$46,'Team matrix'!$A$5:$A$46,"chain cascade same target",'Team matrix'!$B$5:$B$46,"reference"),"") -> 1.89 | C60: =IFERROR(SUMIFS('Team matrix'!$C$5:$C$46,'Team matrix'!$A$5:$A$46,"chain cascade same target",'Team matrix'!$B$5:$B$46,"swarm"),"") -> 1.78 | D60: =IFERROR(SUMIFS('Team matrix'!$C$5:$C$46,'Team matrix'!$A$5:$A$46,"chain cascade same target",'Team matrix'!$B$5:$B$46,"elite"),"") -> 3.07
A61: break shred and vulnerable | B61: =IFERROR(SUMIFS('Team matrix'!$C$5:$C$46,'Team matrix'!$A$5:$A$46,"break shred and vulnerable",'Team matrix'!$B$5:$B$46,"reference"),"") -> 1.85 | C61: =IFERROR(SUMIFS('Team matrix'!$C$5:$C$46,'Team matrix'!$A$5:$A$46,"break shred and vulnerable",'Team matrix'!$B$5:$B$46,"swarm"),"") -> 1.96 | D61: =IFERROR(SUMIFS('Team matrix'!$C$5:$C$46,'Team matrix'!$A$5:$A$46,"break shred and vulnerable",'Team matrix'!$B$5:$B$46,"elite"),"") -> 2.15
A62: tall fewer upgraded | B62: =IFERROR(SUMIFS('Team matrix'!$C$5:$C$46,'Team matrix'!$A$5:$A$46,"tall fewer upgraded",'Team matrix'!$B$5:$B$46,"reference"),"") -> 0.73 | C62: =IFERROR(SUMIFS('Team matrix'!$C$5:$C$46,'Team matrix'!$A$5:$A$46,"tall fewer upgraded",'Team matrix'!$B$5:$B$46,"swarm"),"") -> 0.73 | D62: =IFERROR(SUMIFS('Team matrix'!$C$5:$C$46,'Team matrix'!$A$5:$A$46,"tall fewer upgraded",'Team matrix'!$B$5:$B$46,"elite"),"") -> 1.39
A63: wide more unupgraded | B63: =IFERROR(SUMIFS('Team matrix'!$C$5:$C$46,'Team matrix'!$A$5:$A$46,"wide more unupgraded",'Team matrix'!$B$5:$B$46,"reference"),"") -> 0.8 | C63: =IFERROR(SUMIFS('Team matrix'!$C$5:$C$46,'Team matrix'!$A$5:$A$46,"wide more unupgraded",'Team matrix'!$B$5:$B$46,"swarm"),"") -> 0.77 | D63: =IFERROR(SUMIFS('Team matrix'!$C$5:$C$46,'Team matrix'!$A$5:$A$46,"wide more unupgraded",'Team matrix'!$B$5:$B$46,"elite"),"") -> 1.5
A64: hybrid dots + cascade | B64: =IFERROR(SUMIFS('Team matrix'!$C$5:$C$46,'Team matrix'!$A$5:$A$46,"hybrid dots + cascade",'Team matrix'!$B$5:$B$46,"reference"),"") -> 1.63 | C64: =IFERROR(SUMIFS('Team matrix'!$C$5:$C$46,'Team matrix'!$A$5:$A$46,"hybrid dots + cascade",'Team matrix'!$B$5:$B$46,"swarm"),"") -> 1.61 | D64: =IFERROR(SUMIFS('Team matrix'!$C$5:$C$46,'Team matrix'!$A$5:$A$46,"hybrid dots + cascade",'Team matrix'!$B$5:$B$46,"elite"),"") -> 2.63
A65: hybrid dots + detonator | B65: =IFERROR(SUMIFS('Team matrix'!$C$5:$C$46,'Team matrix'!$A$5:$A$46,"hybrid dots + detonator",'Team matrix'!$B$5:$B$46,"reference"),"") -> 1.61 | C65: =IFERROR(SUMIFS('Team matrix'!$C$5:$C$46,'Team matrix'!$A$5:$A$46,"hybrid dots + detonator",'Team matrix'!$B$5:$B$46,"swarm"),"") -> 1.56 | D65: =IFERROR(SUMIFS('Team matrix'!$C$5:$C$46,'Team matrix'!$A$5:$A$46,"hybrid dots + detonator",'Team matrix'!$B$5:$B$46,"elite"),"") -> 2.2
A68: B Escalation — does the build come online?
A69: Late-fight damage over early. Above 1.0 means it grows through the fight.
B70: reference | C70: swarm | D70: elite
A71: control plain damage | B71: =IFERROR(SUMIFS('Team matrix'!$L$5:$L$46,'Team matrix'!$A$5:$A$46,"control plain damage",'Team matrix'!$B$5:$B$46,"reference"),"") -> 0.48 | C71: =IFERROR(SUMIFS('Team matrix'!$L$5:$L$46,'Team matrix'!$A$5:$A$46,"control plain damage",'Team matrix'!$B$5:$B$46,"swarm"),"") -> 0.58 | D71: =IFERROR(SUMIFS('Team matrix'!$L$5:$L$46,'Team matrix'!$A$5:$A$46,"control plain damage",'Team matrix'!$B$5:$B$46,"elite"),"") -> 0.55
A72: control all AoE | B72: =IFERROR(SUMIFS('Team matrix'!$L$5:$L$46,'Team matrix'!$A$5:$A$46,"control all AoE",'Team matrix'!$B$5:$B$46,"reference"),"") -> 0.28 | C72: =IFERROR(SUMIFS('Team matrix'!$L$5:$L$46,'Team matrix'!$A$5:$A$46,"control all AoE",'Team matrix'!$B$5:$B$46,"swarm"),"") -> 0.4 | D72: =IFERROR(SUMIFS('Team matrix'!$L$5:$L$46,'Team matrix'!$A$5:$A$46,"control all AoE",'Team matrix'!$B$5:$B$46,"elite"),"") -> 0.61
A73: heavy dot 1 type big ticks | B73: =IFERROR(SUMIFS('Team matrix'!$L$5:$L$46,'Team matrix'!$A$5:$A$46,"heavy dot 1 type big ticks",'Team matrix'!$B$5:$B$46,"reference"),"") -> 1.09 | C73: =IFERROR(SUMIFS('Team matrix'!$L$5:$L$46,'Team matrix'!$A$5:$A$46,"heavy dot 1 type big ticks",'Team matrix'!$B$5:$B$46,"swarm"),"") -> 0.54 | D73: =IFERROR(SUMIFS('Team matrix'!$L$5:$L$46,'Team matrix'!$A$5:$A$46,"heavy dot 1 type big ticks",'Team matrix'!$B$5:$B$46,"elite"),"") -> 0.91
A74: heavy dot no support | B74: =IFERROR(SUMIFS('Team matrix'!$L$5:$L$46,'Team matrix'!$A$5:$A$46,"heavy dot no support",'Team matrix'!$B$5:$B$46,"reference"),"") -> 1 | C74: =IFERROR(SUMIFS('Team matrix'!$L$5:$L$46,'Team matrix'!$A$5:$A$46,"heavy dot no support",'Team matrix'!$B$5:$B$46,"swarm"),"") -> 0.75 | D74: =IFERROR(SUMIFS('Team matrix'!$L$5:$L$46,'Team matrix'!$A$5:$A$46,"heavy dot no support",'Team matrix'!$B$5:$B$46,"elite"),"") -> 0.94
...

Sheet Enemy counters
A1: Enemy archetypes and what they punish
A2: Every enemy is a different problem, not a bigger health bar. Nine archetypes, each mixed five-into-eleven-chaff so the encounter stays realistic.
A4: archetype | B4: what it does
A5: chaff | B5: numerous and disposable — the scenario where your build simply works
A6: bruiser | B6: slow, heavy, high health — a general tax on everyone
A7: skirmisher | B7: fast, strikes past the front row
A8: warden | B8: thick shields and shelters the others — blunts direct damage, but shields do nothing against decay
A9: cleanser | B9: strips every ailment off the board and suppresses the next few — the answer to stacking builds
A10: splitter | B10: dies into two chaff — punishes overkill
A11: harrier | B11: many small hits — chews through barriers a big hit would not
A12: anchor | B12: strengthens every other enemy — punishes slow clears
A13: reflector | B13: returns a share of every hit — the answer to cascades and multi-hit
A16: A Breakpoint against each archetype
A17: Difficulty multiplier at which the build stops winning three fights in four.
A18: build | B18: chaff | C18: bruiser | D18: skirmisher | E18: warden | F18: cleanser | G18: splitter | H18: harrier | I18: anchor | J18: reflector
A19: control plain damage | B19: 1.74 | C19: 0.95 | D19: 1.12 | E19: 0.92 | F19: 1.09 | G19: 1.05 | H19: 1.05 | I19: 1.16 | J19: 1.12
A20: control all AoE | B20: 2.57 | C20: 1.57 | D20: 1.81 | E20: 2.19 | F20: 1.74 | G20: 1.84 | H20: 1.71 | I20: 2.57 | J20: 1.67
A21: heavy dot 1 type big ticks | B21: 2.57 | C21: 2.12 | D21: 2.05 | E21: 2.57 | F21: 1.95 | G21: 2.53 | H21: 2.15 | I21: 2.57 | J21: 2.46
A22: heavy dot no support | B22: 2.57 | C22: 1.74 | D22: 1.81 | E22: 2.57 | F22: 1.84 | G22: 2.05 | H22: 1.71 | I22: 2.57 | J22: 1.95
A23: wide dot 4 types many hits | B23: 2.57 | C23: 1.53 | D23: 1.64 | E23: 2.57 | F23: 1.71 | G23: 1.84 | H23: 1.53 | I23: 2.36 | J23: 1.84
A24: wide dot 4 types no support | B24: 2.29 | C24: 1.36 | D24: 1.5 | E24: 2.46 | F24: 1.64 | G24: 1.64 | H24: 1.43 | I24: 2.29 | J24: 1.6
A25: detonator stacks then burst | B25: 2.57 | C25: 1.57 | D25: 1.77 | E25: 2.57 | F25: 1.91 | G25: 1.95 | H25: 1.71 | I25: 2.57 | J25: 1.95
A26: chain follow-up cascade | B26: 2.57 | C26: 1.53 | D26: 1.95 | E26: 2.53 | F26: 1.77 | G26: 1.95 | H26: 1.84 | I26: 2.57 | J26: 1.57
A27: chain cascade same target | B27: 2.57 | C27: 1.84 | D27: 2.29 | E27: 2.57 | F27: 2.02 | G27: 2.29 | H27: 2.19 | I27: 2.57 | J27: 1.77
A28: break shred and vulnerable | B28: 2.57 | C28: 1.4 | D28: 1.71 | E28: 2.05 | F28: 1.6 | G28: 1.71 | H28: 1.67 | I28: 2.22 | J28: 1.57
A29: tall fewer upgraded | B29: 1.36 | C29: 0.78 | D29: 0.85 | E29: 0.88 | F29: 0.85 | G29: 0.85 | H29: 0.85 | I29: 1.19 | J29: 0.85
A30: wide more unupgraded | B30: 1.53 | C30: 0.78 | D30: 0.92 | E30: 0.78 | F30: 0.92 | G30: 0.85 | H30: 0.85 | I30: 0.92 | J30: 1.02
... A32: hybrid dots + detonator | B32: 2.57 | C32: 1.6 | D32: 1.84 | E32: 2.57 | F32: 1.84 | G32: 1.95 | H32: 1.71 | I32: 2.57 | J32: 1.95
A35: B Relative — how each archetype treats each build
A36: Each row divided by its own average. Below 0.85 is a hard counter; above 1.10 is a favourable matchup.
A37: build | B37: chaff | C37: bruiser | D37: skirmisher | E37: warden | F37: cleanser | G37: splitter | H37: harrier | I37: anchor | J37: reflector
A38: control plain damage | B38: 1.6 | C38: 0.87 | D38: 1.03 | E38: 0.84 | F38: 1 | G38: 0.96 | H38: 0.96 | I38: 1.06 | J38: 1.03
A39: control all AoE | B39: 1.42 | C39: 0.87 | D39: 1 | E39: 1.21 | F39: 0.96 | G39: 1.02 | H39: 0.94 | I39: 1.42 | J39: 0.92
A40: heavy dot 1 type big ticks | B40: 1.04 | C40: 0.86 | D40: 0.83 | E40: 1.04 | F40: 0.79 | G40: 1.03 | H40: 0.87 | I40: 1.04 | J40: 1
A41: heavy dot no support | B41: 1.32 | C41: 0.89 | D41: 0.93 | E41: 1.32 | F41: 0.94 | G41: 1.05 | H41: 0.88 | I41: 1.32 | J41: 1
A42: wide dot 4 types many hits | B42: 1.4 | C42: 0.83 | D42: 0.89 | E42: 1.4 | F42: 0.93 | G42: 1 | H42: 0.83 | I42: 1.28 | J42: 1
A43: wide dot 4 types no support | B43: 1.4 | C43: 0.83 | D43: 0.91 | E43: 1.5 | F43: 1 | G43: 1 | H43: 0.87 | I43: 1.4 | J43: 0.98
A44: detonator stacks then burst | B44: 1.32 | C44: 0.81 | D44: 0.91 | E44: 1.32 | F44: 0.98 | G44: 1 | H44: 0.88 | I44: 1.32 | J44: 1
A45: chain follow-up cascade | B45: 1.32 | C45: 0.78 | D45: 1 | E45: 1.3 | F45: 0.91 | G45: 1 | H45: 0.94 | I45: 1.32 | J45: 0.81
A46: chain cascade same target | B46: 1.12 | C46: 0.8 | D46: 1 | E46: 1.12 | F46: 0.88 | G46: 1 | H46: 0.96 | I46: 1.12 | J46: 0.77
...

Sheet Summary
A1: Battle test summary
A2: Averages over 250 simulated fights per configuration. Every cell is a formula over the Results sheet.
A4: 1 Does a bigger enemy field make fights longer?
A5: Win %, then average fight minutes. Enemy pool held at 20.
B6: 3 on field | C6: 6 on field | D6: 9 on field
A7: AoE team | B7: =IFERROR(AVERAGEIFS(Results!$N$2:$N$241,Results!$A$2:$A$241,"aoe",Results!$B$2:$B$241,3,Results!$C$2:$C$241,20)&" / "&TEXT(AVERAGEIFS(Results!$F$2:$F$241,Results!$A$2:$A$241,"aoe",Results!$B$2:$B$241,3,Results!$C$2:$C$241,20),"0.0")&"%","") -> 1.67115833333333 / 99.0% | C7: =IFERROR(AVERAGEIFS(Results!$N$2:$N$241,Results!$A$2:$A$241,"aoe",Results!$B$2:$B$241,6,Results!$C$2:$C$241,20)&" / "&TEXT(AVERAGEIFS(Results!$F$2:$F$241,Results!$A$2:$A$241,"aoe",Results!$B$2:$B$241,6,Results!$C$2:$C$241,20),"0.0")&"%","") -> 1.279525 / 98.6% | D7: =IFERROR(AVERAGEIFS(Results!$N$2:$N$241,Results!$A$2:$A$241,"aoe",Results!$B$2:$B$241,9,Results!$C$2:$C$241,20)&" / "&TEXT(AVERAGEIFS(Results!$F$2:$F$241,Results!$A$2:$A$241,"aoe",Results!$B$2:$B$241,9,Results!$C$2:$C$241,20),"0.0")&"%","") -> 1.22863333333333 / 96.7%
A8: Single target | B8: =IFERROR(AVERAGEIFS(Results!$N$2:$N$241,Results!$A$2:$A$241,"single",Results!$B$2:$B$241,3,Results!$C$2:$C$241,20)&" / "&TEXT(AVERAGEIFS(Results!$F$2:$F$241,Results!$A$2:$A$241,"single",Results!$B$2:$B$241,3,Results!$C$2:$C$241,20),"0.0")&"%","") -> 1.5097 / 0.0% | C8: =IFERROR(AVERAGEIFS(Results!$N$2:$N$241,Results!$A$2:$A$241,"single",Results!$B$2:$B$241,6,Results!$C$2:$C$241,20)&" / "&TEXT(AVERAGEIFS(Results!$F$2:$F$241,Results!$A$2:$A$241,"single",Results!$B$2:$B$241,6,Results!$C$2:$C$241,20),"0.0")&"%","") -> 1.30613333333333 / 0.0% | D8: =IFERROR(AVERAGEIFS(Results!$N$2:$N$241,Results!$A$2:$A$241,"single",Results!$B$2:$B$241,9,Results!$C$2:$C$241,20)&" / "&TEXT(AVERAGEIFS(Results!$F$2:$F$241,Results!$A$2:$A$241,"single",Results!$B$2:$B$241,9,Results!$C$2:$C$241,20),"0.0")&"%","") -> 1.37795 / 0.4%
A9: Mixed | B9: =IFERROR(AVERAGEIFS(Results!$N$2:$N$241,Results!$A$2:$A$241,"mixed",Results!$B$2:$B$241,3,Results!$C$2:$C$241,20)&" / "&TEXT(AVERAGEIFS(Results!$F$2:$F$241,Results!$A$2:$A$241,"mixed",Results!$B$2:$B$241,3,Results!$C$2:$C$241,20),"0.0")&"%","") -> 1.96720833333333 / 46.3% | C9: =IFERROR(AVERAGEIFS(Results!$N$2:$N$241,Results!$A$2:$A$241,"mixed",Results!$B$2:$B$241,6,Results!$C$2:$C$241,20)&" / "&TEXT(AVERAGEIFS(Results!$F$2:$F$241,Results!$A$2:$A$241,"mixed",Results!$B$2:$B$241,6,Results!$C$2:$C$241,20),"0.0")&"%","") -> 1.57195833333333 / 11.6% | D9: =IFERROR(AVERAGEIFS(Results!$N$2:$N$241,Results!$A$2:$A$241,"mixed",Results!$B$2:$B$241,9,Results!$C$2:$C$241,20)&" / "&TEXT(AVERAGEIFS(Results!$F$2:$F$241,Results!$A$2:$A$241,"mixed",Results!$B$2:$B$241,9,Results!$C$2:$C$241,20),"0.0")&"%","") -> 1.51615833333333 / 23.6%
A12: 2 How does total enemy count split the archetypes?
A13: Win rate. Field size 9. Higher pool means more reinforcements cycling in.
B14: 6 enemies | C14: 12 enemies | D14: 20 enemies
A15: AoE team | B15: =IFERROR(AVERAGEIFS(Results!$F$2:$F$241,Results!$A$2:$A$241,"aoe",Results!$B$2:$B$241,9,Results!$C$2:$C$241,6),"") | C15: =IFERROR(AVERAGEIFS(Results!$F$2:$F$241,Results!$A$2:$A$241,"aoe",Results!$B$2:$B$241,9,Results!$C$2:$C$241,12),"") -> 100 | D15: =IFERROR(AVERAGEIFS(Results!$F$2:$F$241,Results!$A$2:$A$241,"aoe",Results!$B$2:$B$241,9,Results!$C$2:$C$241,20),"") -> 96.68
A16: Single target | B16: =IFERROR(AVERAGEIFS(Results!$F$2:$F$241,Results!$A$2:$A$241,"single",Results!$B$2:$B$241,9,Results!$C$2:$C$241,6),"") | C16: =IFERROR(AVERAGEIFS(Results!$F$2:$F$241,Results!$A$2:$A$241,"single",Results!$B$2:$B$241,9,Results!$C$2:$C$241,12),"") -> 34.24 | D16: =IFERROR(AVERAGEIFS(Results!$F$2:$F$241,Results!$A$2:$A$241,"single",Results!$B$2:$B$241,9,Results!$C$2:$C$241,20),"") -> 0.44
A17: Mixed | B17: =IFERROR(AVERAGEIFS(Results!$F$2:$F$241,Results!$A$2:$A$241,"mixed",Results!$B$2:$B$241,9,Results!$C$2:$C$241,6),"") | C17: =IFERROR(AVERAGEIFS(Results!$F$2:$F$241,Results!$A$2:$A$241,"mixed",Results!$B$2:$B$241,9,Results!$C$2:$C$241,12),"") -> 91.6 | D17: =IFERROR(AVERAGEIFS(Results!$F$2:$F$241,Results!$A$2:$A$241,"mixed",Results!$B$2:$B$241,9,Results!$C$2:$C$241,20),"") -> 23.56
A20: 3 Are the three harmonies equivalent?
A21: Win rate at 4 members, averaged over every field size and pool.
B22: none | C22: cascade | D22: break | E22: detonation
A23: AoE team | B23: =IFERROR(AVERAGEIFS(Results!$F$2:$F$241,Results!$A$2:$A$241,"aoe",Results!$D$2:$D$241,"none"),"") -> 95.85 | C23: =IFERROR(AVERAGEIFS(Results!$F$2:$F$241,Results!$A$2:$A$241,"aoe",Results!$D$2:$D$241,"cascade"),"") -> 99 | D23: =IFERROR(AVERAGEIFS(Results!$F$2:$F$241,Results!$A$2:$A$241,"aoe",Results!$D$2:$D$241,"break"),"") -> 100 | E23: =IFERROR(AVERAGEIFS(Results!$F$2:$F$241,Results!$A$2:$A$241,"aoe",Results!$D$2:$D$241,"detonation"),"") -> 100
A24: Single target | B24: =IFERROR(AVERAGEIFS(Results!$F$2:$F$241,Results!$A$2:$A$241,"single",Results!$D$2:$D$241,"none"),"") -> 25 | C24: =IFERROR(AVERAGEIFS(Results!$F$2:$F$241,Results!$A$2:$A$241,"single",Results!$D$2:$D$241,"cascade"),"") -> 25 | D24: =IFERROR(AVERAGEIFS(Results!$F$2:$F$241,Results!$A$2:$A$241,"single",Results!$D$2:$D$241,"break"),"") -> 44.983333 | E24: =IFERROR(AVERAGEIFS(Results!$F$2:$F$241,Results!$A$2:$A$241,"single",Results!$D$2:$D$241,"detonation"),"") -> 56.566667
A25: Mixed | B25: =IFERROR(AVERAGEIFS(Results!$F$2:$F$241,Results!$A$2:$A$241,"mixed",Results!$D$2:$D$241,"none"),"") -> 49.7 | C25: =IFERROR(AVERAGEIFS(Results!$F$2:$F$241,Results!$A$2:$A$241,"mixed",Results!$D$2:$D$241,"cascade"),"") -> 61.883333 | D25: =IFERROR(AVERAGEIFS(Results!$F$2:$F$241,Results!$A$2:$A$241,"mixed",Results!$D$2:$D$241,"break"),"") -> 80.366667 | E25: =IFERROR(AVERAGEIFS(Results!$F$2:$F$241,Results!$A$2:$A$241,"mixed",Results!$D$2:$D$241,"detonation"),"") -> 76.283333
A28: 4 Does each harmony scale with how many members you field?
A29: Win rate by member count, all teams and encounters pooled.
B30: 2 members | C30: 3 members | D30: 4 members
A31: Cascade | B31: =IFERROR(AVERAGEIFS(Results!$F$2:$F$241,Results!$D$2:$D$241,"cascade",Results!$E$2:$E$241,2),"") -> 60.583333 | C31: =IFERROR(AVERAGEIFS(Results!$F$2:$F$241,Results!$D$2:$D$241,"cascade",Results!$E$2:$E$241,3),"") -> 61.933333 | D31: =IFERROR(AVERAGEIFS(Results!$F$2:$F$241,Results!$D$2:$D$241,"cascade",Results!$E$2:$E$241,4),"") -> 63.366667
A32: Break efficiency | B32: =IFERROR(AVERAGEIFS(Results!$F$2:$F$241,Results!$D$2:$D$241,"break",Results!$E$2:$E$241,2),"") -> 69.933333 | C32: =IFERROR(AVERAGEIFS(Results!$F$2:$F$241,Results!$D$2:$D$241,"break",Results!$E$2:$E$241,3),"") -> 74.7 | D32: =IFERROR(AVERAGEIFS(Results!$F$2:$F$241,Results!$D$2:$D$241,"break",Results!$E$2:$E$241,4),"") -> 80.716667
A33: Detonation | B33: =IFERROR(AVERAGEIFS(Results!$F$2:$F$241,Results!$D$2:$D$241,"detonation",Results!$E$2:$E$241,2),"") -> 74.716667 | C33: =IFERROR(AVERAGEIFS(Results!$F$2:$F$241,Results!$D$2:$D$241,"detonation",Results!$E$2:$E$241,3),"") -> 78.416667 | D33: =IFERROR(AVERAGEIFS(Results!$F$2:$F$241,Results!$D$2:$D$241,"detonation",Results!$E$2:$E$241,4),"") -> 79.716667
A36: 5 How many fights of each shape fit in a session?
A37: Fights per session at the target length on the Parameters sheet.
B38: 3 on field | C38: 6 on field | D38: 9 on field
A39: AoE team | B39: =IFERROR(Parameters!$B$8/AVERAGEIFS(Results!$N$2:$N$241,Results!$A$2:$A$241,"aoe",Results!$B$2:$B$241,3,Results!$C$2:$C$241,20),"") -> 28.124205 | C39: =IFERROR(Parameters!$B$8/AVERAGEIFS(Results!$N$2:$N$241,Results!$A$2:$A$241,"aoe",Results!$B$2:$B$241,6,Results!$C$2:$C$241,20),"") -> 36.732381 | D39: =IFERROR(Parameters!$B$8/AVERAGEIFS(Results!$N$2:$N$241,Results!$A$2:$A$241,"aoe",Results!$B$2:$B$241,9,Results!$C$2:$C$241,20),"") -> 38.253886
A40: Single target | B40: =IFERROR(Parameters!$B$8/AVERAGEIFS(Results!$N$2:$N$241,Results!$A$2:$A$241,"single",Results!$B$2:$B$241,3,Results!$C$2:$C$241,20),"") -> 31.132013 | C40: =IFERROR(Parameters!$B$8/AVERAGEIFS(Results!$N$2:$N$241,Results!$A$2:$A$241,"single",Results!$B$2:$B$241,6,Results!$C$2:$C$241,20),"") -> 35.984075 | D40: =IFERROR(Parameters!$B$8/AVERAGEIFS(Results!$N$2:$N$241,Results!$A$2:$A$241,"single",Results!$B$2:$B$241,9,Results!$C$2:$C$241,20),"") -> 34.10864
A41: Mixed | B41: =IFERROR(Parameters!$B$8/AVERAGEIFS(Results!$N$2:$N$241,Results!$A$2:$A$241,"mixed",Results!$B$2:$B$241,3,Results!$C$2:$C$241,20),"") -> 23.891725 | C41: =IFERROR(Parameters!$B$8/AVERAGEIFS(Results!$N$2:$N$241,Results!$A$2:$A$241,"mixed",Results!$B$2:$B$241,6,Results!$C$2:$C$241,20),"") -> 29.899011 | D41: =IFERROR(Parameters!$B$8/AVERAGEIFS(Results!$N$2:$N$241,Results!$A$2:$A$241,"mixed",Results!$B$2:$B$241,9,Results!$C$2:$C$241,20),"") -> 30.999401

Sheet Follow-up chains
A1: Follow-up chain testing
A2: Follow-ups may trigger further follow-ups. Each reactor has a budget per triggering action; a global cap of 12 stops runaway. 250 fights per row.
A3: Trigger types in the test crew: on ally attack, on being hit, on a marked enemy being hit, on shield break. One reactor lands two hits per trigger.
A5: encounter | B5: reactors | C5: budget | D5: chaff hp | E5: follow ups | F5: mean chain | G5: max chain | H5: chains 5plus | I5: chains 8plus | J5: win pct | K5: chain per followup
A6: 20 chaff + elites | B6: 3 | C6: 2 | D6: 26 | E6: 25.4 | F6: 1.89 | G6: 4 | H6: 0 | I6: 0 | J6: 0 | K6: =IF(E6=0,0,F6/E6) -> 0.074409449
A7: 20 chaff + elites | B7: 3 | C7: 2 | D7: 40 | E7: 38.7 | F7: 2.9 | G7: 4 | H7: 0 | I7: 0 | J7: 0 | K7: =IF(E7=0,0,F7/E7) -> 0.074935401
A8: 20 chaff + elites | B8: 3 | C8: 2 | D8: 60 | E8: 38.8 | F8: 3.11 | G8: 5 | H8: 0.1 | I8: 0 | J8: 0 | K8: =IF(E8=0,0,F8/E8) -> 0.080154639
A9: 20 chaff + elites | B9: 3 | C9: 3 | D9: 26 | E9: 39 | F9: 2.39 | G9: 7 | H9: 2.72 | I9: 0 | J9: 6.4 | K9: =IF(E9=0,0,F9/E9) -> 0.061282051
A10: 20 chaff + elites | B10: 3 | C10: 3 | D10: 40 | E10: 56.2 | F10: 3.45 | G10: 7 | H10: 3.8 | I10: 0 | J10: 6.4 | K10: =IF(E10=0,0,F10/E10) -> 0.0613879
A11: 20 chaff + elites | B11: 3 | C11: 3 | D11: 60 | E11: 56.3 | F11: 4.31 | G11: 7 | H11: 5.72 | I11: 0 | J11: 0 | K11: =IF(E11=0,0,F11/E11) -> 0.076554174
A12: 20 chaff + elites | B12: 3 | C12: 4 | D12: 26 | E12: 41.6 | F12: 2.55 | G12: 9 | H12: 2.59 | I12: 0.35 | J12: 8 | K12: =IF(E12=0,0,F12/E12) -> 0.061298077
A13: 20 chaff + elites | B13: 3 | C13: 4 | D13: 40 | E13: 58.9 | F13: 3.62 | G13: 9 | H13: 3.68 | I13: 2.42 | J13: 8 | K13: =IF(E13=0,0,F13/E13) -> 0.061460102
A14: 20 chaff + elites | B14: 3 | C14: 4 | D14: 60 | E14: 61.2 | F14: 4.6 | G14: 9 | H14: 5.77 | I14: 1.82 | J14: 0 | K14: =IF(E14=0,0,F14/E14) -> 0.075163399
A15: 20 chaff + elites | B15: 4 | C15: 2 | D15: 26 | E15: 76.6 | F15: 2.72 | G15: 6 | H15: 5.56 | I15: 0 | J15: 100 | K15: =IF(E15=0,0,F15/E15) -> 0.035509138
A16: 20 chaff + elites | B16: 4 | C16: 2 | D16: 40 | E16: 93.6 | F16: 3.21 | G16: 6 | H16: 5.76 | I16: 0 | J16: 100 | K16: =IF(E16=0,0,F16/E16) -> 0.034294872
A17: 20 chaff + elites | B17: 4 | C17: 2 | D17: 60 | E17: 120.2 | F17: 4.01 | G17: 6 | H17: 10.52 | I17: 0 | J17: 100 | K17: =IF(E17=0,0,F17/E17) -> 0.033361065
... A86: 6 elites | B86: 5 | C86: 4 | D86: 60 | E86: 45.5 | F86: 3.87 | G86: 12 | H86: 3.34 | I86: 1.52 | J86: 100 | K86: =IF(E86=0,0,F86/E86) -> 0.085054945
A89: A Mean chain length
A90: How many follow-ups a single hit sets off, by target toughness.
B91: 26 hp chaff | C91: 40 hp chaff | D91: 60 hp chaff
A92: 3 reactors | B92: =IFERROR(AVERAGEIFS('Follow-up chains'!$F$6:$F$86,'Follow-up chains'!$B$6:$B$86,3,'Follow-up chains'!$D$6:$D$86,26),"") -> 3.0433333 | C92: =IFERROR(AVERAGEIFS('Follow-up chains'!$F$6:$F$86,'Follow-up chains'!$B$6:$B$86,3,'Follow-up chains'!$D$6:$D$86,40),"") -> 3.8577778 | D92: =IFERROR(AVERAGEIFS('Follow-up chains'!$F$6:$F$86,'Follow-up chains'!$B$6:$B$86,3,'Follow-up chains'!$D$6:$D$86,60),"") -> 4.2244444
A93: 4 reactors | B93: =IFERROR(AVERAGEIFS('Follow-up chains'!$F$6:$F$86,'Follow-up chains'!$B$6:$B$86,4,'Follow-up chains'!$D$6:$D$86,26),"") -> 3.14 | C93: =IFERROR(AVERAGEIFS('Follow-up chains'!$F$6:$F$86,'Follow-up chains'!$B$6:$B$86,4,'Follow-up chains'!$D$6:$D$86,40),"") -> 3.7033333 | D93: =IFERROR(AVERAGEIFS('Follow-up chains'!$F$6:$F$86,'Follow-up chains'!$B$6:$B$86,4,'Follow-up chains'!$D$6:$D$86,60),"") -> 4.23
A94: 5 reactors | B94: =IFERROR(AVERAGEIFS('Follow-up chains'!$F$6:$F$86,'Follow-up chains'!$B$6:$B$86,5,'Follow-up chains'!$D$6:$D$86,26),"") -> 3.9488889 | C94: =IFERROR(AVERAGEIFS('Follow-up chains'!$F$6:$F$86,'Follow-up chains'!$B$6:$B$86,5,'Follow-up chains'!$D$6:$D$86,40),"") -> 4.3322222 | D94: =IFERROR(AVERAGEIFS('Follow-up chains'!$F$6:$F$86,'Follow-up chains'!$B$6:$B$86,5,'Follow-up chains'!$D$6:$D$86,60),"") -> 4.0844444
A97: B Chains of five or more per fight
A98: The spectacle metric. Averaged over every budget.
B99: 26 hp chaff | C99: 40 hp chaff | D99: 60 hp chaff
A100: 3 reactors | B100: =IFERROR(AVERAGEIFS('Follow-up chains'!$H$6:$H$86,'Follow-up chains'!$B$6:$B$86,3,'Follow-up chains'!$D$6:$D$86,26),"") -> 2.4633333 | C100: =IFERROR(AVERAGEIFS('Follow-up chains'!$H$6:$H$86,'Follow-up chains'!$B$6:$B$86,3,'Follow-up chains'!$D$6:$D$86,40),"") -> 3.4822222 | D100: =IFERROR(AVERAGEIFS('Follow-up chains'!$H$6:$H$86,'Follow-up chains'!$B$6:$B$86,3,'Follow-up chains'!$D$6:$D$86,60),"") -> 4.6322222
A101: 4 reactors | B101: =IFERROR(AVERAGEIFS('Follow-up chains'!$H$6:$H$86,'Follow-up chains'!$B$6:$B$86,4,'Follow-up chains'!$D$6:$D$86,26),"") -> 3.7033333 | C101: =IFERROR(AVERAGEIFS('Follow-up chains'!$H$6:$H$86,'Follow-up chains'!$B$6:$B$86,4,'Follow-up chains'!$D$6:$D$86,40),"") -> 4.3311111 | D101: =IFERROR(AVERAGEIFS('Follow-up chains'!$H$6:$H$86,'Follow-up chains'!$B$6:$B$86,4,'Follow-up chains'!$D$6:$D$86,60),"") -> 6.6677778
A102: 5 reactors | B102: =IFERROR(AVERAGEIFS('Follow-up chains'!$H$6:$H$86,'Follow-up chains'!$B$6:$B$86,5,'Follow-up chains'!$D$6:$D$86,26),"") -> 3.9733333 | C102: =IFERROR(AVERAGEIFS('Follow-up chains'!$H$6:$H$86,'Follow-up chains'!$B$6:$B$86,5,'Follow-up chains'!$D$6:$D$86,40),"") -> 6.7333333 | D102: =IFERROR(AVERAGEIFS('Follow-up chains'!$H$6:$H$86,'Follow-up chains'!$B$6:$B$86,5,'Follow-up chains'!$D$6:$D$86,60),"") -> 8.5444444
A105: C Total follow-ups per fight
A106: Volume, by encounter shape. Five reactors.
B107: 20 chaff + elites | C107: 12 mixed | D107: 6 elites
A108: budget 2 | B108: =IFERROR(AVERAGEIFS('Follow-up chains'!$E$6:$E$86,'Follow-up chains'!$B$6:$B$86,5,'Follow-up chains'!$C$6:$C$86,2,'Follow-up chains'!$A$6:$A$86,"20 chaff + elites"),"") -> 126.73333 | C108: =IFERROR(AVERAGEIFS('Follow-up chains'!$E$6:$E$86,'Follow-up chains'!$B$6:$B$86,5,'Follow-up chains'!$C$6:$C$86,2,'Follow-up chains'!$A$6:$A$86,"12 mixed"),"") -> 76.2 | D108: =IFERROR(AVERAGEIFS('Follow-up chains'!$E$6:$E$86,'Follow-up chains'!$B$6:$B$86,5,'Follow-up chains'!$C$6:$C$86,2,'Follow-up chains'!$A$6:$A$86,"6 elites"),"") -> 38.333333
A109: budget 3 | B109: =IFERROR(AVERAGEIFS('Follow-up chains'!$E$6:$E$86,'Follow-up chains'!$B$6:$B$86,5,'Follow-up chains'!$C$6:$C$86,3,'Follow-up chains'!$A$6:$A$86,"20 chaff + elites"),"") -> 132.26667 | C109: =IFERROR(AVERAGEIFS('Follow-up chains'!$E$6:$E$86,'Follow-up chains'!$B$6:$B$86,5,'Follow-up chains'!$C$6:$C$86,3,'Follow-up chains'!$A$6:$A$86,"12 mixed"),"") -> 79.666667 | D109: =IFERROR(AVERAGEIFS('Follow-up chains'!$E$6:$E$86,'Follow-up chains'!$B$6:$B$86,5,'Follow-up chains'!$C$6:$C$86,3,'Follow-up chains'!$A$6:$A$86,"6 elites"),"") -> 41.1
A110: budget 4 | B110: =IFERROR(AVERAGEIFS('Follow-up chains'!$E$6:$E$86,'Follow-up chains'!$B$6:$B$86,5,'Follow-up chains'!$C$6:$C$86,4,'Follow-up chains'!$A$6:$A$86,"20 chaff + elites"),"") -> 129.46667 | C110: =IFERROR(AVERAGEIFS('Follow-up chains'!$E$6:$E$86,'Follow-up chains'!$B$6:$B$86,5,'Follow-up chains'!$C$6:$C$86,4,'Follow-up chains'!$A$6:$A$86,"12 mixed"),"") -> 77.766667 | D110: =IFERROR(AVERAGEIFS('Follow-up chains'!$E$6:$E$86,'Follow-up chains'!$B$6:$B$86,5,'Follow-up chains'!$C$6:$C$86,4,'Follow-up chains'!$A$6:$A$86,"6 elites"),"") -> 40
A113: D Does more budget lengthen the chain?
A114: Mean chain by budget. If it flattens or falls, lethality is the limit, not budget.
B115: 20 chaff + elites | C115: 12 mixed | D115: 6 elites
A116: budget 2 | B116: =IFERROR(AVERAGEIFS('Follow-up chains'!$F$6:$F$86,'Follow-up chains'!$C$6:$C$86,2,'Follow-up chains'!$A$6:$A$86,"20 chaff + elites"),"") -> 3.2988889 | C116: =IFERROR(AVERAGEIFS('Follow-up chains'!$F$6:$F$86,'Follow-up chains'!$C$6:$C$86,2,'Follow-up chains'!$A$6:$A$86,"12 mixed"),"") -> 3.4833333 | D116: =IFERROR(AVERAGEIFS('Follow-up chains'!$F$6:$F$86,'Follow-up chains'!$C$6:$C$86,2,'Follow-up chains'!$A$6:$A$86,"6 elites"),"") -> 3.4011111
A117: budget 3 | B117: =IFERROR(AVERAGEIFS('Follow-up chains'!$F$6:$F$86,'Follow-up chains'!$C$6:$C$86,3,'Follow-up chains'!$A$6:$A$86,"20 chaff + elites"),"") -> 3.8177778 | C117: =IFERROR(AVERAGEIFS('Follow-up chains'!$F$6:$F$86,'Follow-up chains'!$C$6:$C$86,3,'Follow-up chains'!$A$6:$A$86,"12 mixed"),"") -> 4.1566667 | D117: =IFERROR(AVERAGEIFS('Follow-up chains'!$F$6:$F$86,'Follow-up chains'!$C$6:$C$86,3,'Follow-up chains'!$A$6:$A$86,"6 elites"),"") -> 4.1088889
...

Sheet Retargeting
A1: Follow-up retargeting
A2: same = follow-ups stay on the original target; redirect = move on only when it dies; random = pick any live enemy; spread = always pick a different one.
A3: 250 fights per row. Five reactive units, budget 3 each, chain capped at 12.
A5: crew | B5: mode | C5: pool | D5: field | E5: chaff hp | F5: win pct | G5: rounds | H5: follow ups | I5: mean chain | J5: enemies per chain | K5: chains 5plus | L5: seconds if full action | M5: seconds if quick strike
A6: single | B6: same | C6: 20 | D6: 9 | E6: 26 | F6: 100 | G6: 3.9 | H6: 80.5 | I6: 2.84 | J6: 1 | K6: 5.15 | L6: =H6*Parameters!$B$6 -> 124.775 | M6: =H6*0.3 -> 24.15
A7: single | B7: same | C7: 20 | D7: 9 | E7: 40 | F7: 100 | G7: 3.93 | H7: 100.5 | I7: 3.48 | J7: 1 | K7: 6.87 | L7: =H7*Parameters!$B$6 -> 155.775 | M7: =H7*0.3 -> 30.15
A8: single | B8: same | C8: 12 | D8: 6 | E8: 26 | F8: 100 | G8: 3 | H8: 55 | I8: 3.1 | J8: 1 | K8: 4.39 | L8: =H8*Parameters!$B$6 -> 85.25 | M8: =H8*0.3 -> 16.5
A9: single | B9: same | C9: 12 | D9: 6 | E9: 40 | F9: 100 | G9: 3 | H9: 63.4 | I9: 3.43 | J9: 1 | K9: 4.14 | L9: =H9*Parameters!$B$6 -> 98.27 | M9: =H9*0.3 -> 19.02
A10: single | B10: same | C10: 6 | D10: 4 | E10: 26 | F10: 100 | G10: 2.27 | H10: 25.3 | I10: 2.58 | J10: 1 | K10: 1.07 | L10: =H10*Parameters!$B$6 -> 39.215 | M10: =H10*0.3 -> 7.59
A11: single | B11: same | C11: 6 | D11: 4 | E11: 40 | F11: 100 | G11: 2.36 | H11: 31.9 | I11: 3.17 | J11: 1 | K11: 2.22 | L11: =H11*Parameters!$B$6 -> 49.445 | M11: =H11*0.3 -> 9.57
A12: single | B12: redirect | C12: 20 | D12: 9 | E12: 26 | F12: 88.4 | G12: 4.86 | H12: 98.5 | I12: 5.1 | J12: 2.5 | K12: 10.56 | L12: =H12*Parameters!$B$6 -> 152.675 | M12: =H12*0.3 -> 29.55
A13: single | B13: redirect | C13: 20 | D13: 9 | E13: 40 | F13: 98.4 | G13: 3.26 | H13: 111.8 | I13: 5.24 | J13: 2.48 | K13: 12.26 | L13: =H13*Parameters!$B$6 -> 173.29 | M13: =H13*0.3 -> 33.54
A14: single | B14: redirect | C14: 12 | D14: 6 | E14: 26 | F14: 98.4 | G14: 2.96 | H14: 62.4 | I14: 4.62 | J14: 2.16 | K14: 6.35 | L14: =H14*Parameters!$B$6 -> 96.72 | M14: =H14*0.3 -> 18.72
A15: single | B15: redirect | C15: 12 | D15: 6 | E15: 40 | F15: 97.2 | G15: 3.39 | H15: 70.7 | I15: 4.74 | J15: 2.07 | K15: 7.51 | L15: =H15*Parameters!$B$6 -> 109.585 | M15: =H15*0.3 -> 21.21
A16: single | B16: redirect | C16: 6 | D16: 4 | E16: 26 | F16: 100 | G16: 2.01 | H16: 31 | I16: 4.24 | J16: 1.9 | K16: 2.98 | L16: =H16*Parameters!$B$6 -> 48.05 | M16: =H16*0.3 -> 9.3
A17: single | B17: redirect | C17: 6 | D17: 4 | E17: 40 | F17: 100 | G17: 2.05 | H17: 34.7 | I17: 4.23 | J17: 1.77 | K17: 3.51 | L17: =H17*Parameters!$B$6 -> 53.785 | M17: =H17*0.3 -> 10.41
... A53: aoe | B53: spread | C53: 6 | D53: 4 | E53: 40 | F53: 100 | G53: 6.12 | H53: 0 | I53: 0 | J53: 0 | K53: 0 | L53: =H53*Parameters!$B$6 -> 0 | M53: =H53*0.3 -> 0
A56: A Mean chain length by targeting mode
A57: Single-target crew, 40hp chaff.
B58: 20 enemies | C58: 12 enemies | D58: 6 enemies
A59: same | B59: =IFERROR(AVERAGEIFS(Retargeting!$I$6:$I$53,Retargeting!$A$6:$A$53,"single",Retargeting!$B$6:$B$53,"same",Retargeting!$C$6:$C$53,20,Retargeting!$E$6:$E$53,40),"") -> 3.48 | C59: =IFERROR(AVERAGEIFS(Retargeting!$I$6:$I$53,Retargeting!$A$6:$A$53,"single",Retargeting!$B$6:$B$53,"same",Retargeting!$C$6:$C$53,12,Retargeting!$E$6:$E$53,40),"") -> 3.43 | D59: =IFERROR(AVERAGEIFS(Retargeting!$I$6:$I$53,Retargeting!$A$6:$A$53,"single",Retargeting!$B$6:$B$53,"same",Retargeting!$C$6:$C$53,6,Retargeting!$E$6:$E$53,40),"") -> 3.17
A60: redirect | B60: =IFERROR(AVERAGEIFS(Retargeting!$I$6:$I$53,Retargeting!$A$6:$A$53,"single",Retargeting!$B$6:$B$53,"redirect",Retargeting!$C$6:$C$53,20,Retargeting!$E$6:$E$53,40),"") -> 5.24 | C60: =IFERROR(AVERAGEIFS(Retargeting!$I$6:$I$53,Retargeting!$A$6:$A$53,"single",Retargeting!$B$6:$B$53,"redirect",Retargeting!$C$6:$C$53,12,Retargeting!$E$6:$E$53,40),"") -> 4.74 | D60: =IFERROR(AVERAGEIFS(Retargeting!$I$6:$I$53,Retargeting!$A$6:$A$53,"single",Retargeting!$B$6:$B$53,"redirect",Retargeting!$C$6:$C$53,6,Retargeting!$E$6:$E$53,40),"") -> 4.23
A61: random | B61: =IFERROR(AVERAGEIFS(Retargeting!$I$6:$I$53,Retargeting!$A$6:$A$53,"single",Retargeting!$B$6:$B$53,"random",Retargeting!$C$6:$C$53,20,Retargeting!$E$6:$E$53,40),"") -> 5.57 | C61: =IFERROR(AVERAGEIFS(Retargeting!$I$6:$I$53,Retargeting!$A$6:$A$53,"single",Retargeting!$B$6:$B$53,"random",Retargeting!$C$6:$C$53,12,Retargeting!$E$6:$E$53,40),"") -> 5.11 | D61: =IFERROR(AVERAGEIFS(Retargeting!$I$6:$I$53,Retargeting!$A$6:$A$53,"single",Retargeting!$B$6:$B$53,"random",Retargeting!$C$6:$C$53,6,Retargeting!$E$6:$E$53,40),"") -> 4.61
A62: spread | B62: =IFERROR(AVERAGEIFS(Retargeting!$I$6:$I$53,Retargeting!$A$6:$A$53,"single",Retargeting!$B$6:$B$53,"spread",Retargeting!$C$6:$C$53,20,Retargeting!$E$6:$E$53,40),"") -> 5.56 | C62: =IFERROR(AVERAGEIFS(Retargeting!$I$6:$I$53,Retargeting!$A$6:$A$53,"single",Retargeting!$B$6:$B$53,"spread",Retargeting!$C$6:$C$53,12,Retargeting!$E$6:$E$53,40),"") -> 5.1 | D62: =IFERROR(AVERAGEIFS(Retargeting!$I$6:$I$53,Retargeting!$A$6:$A$53,"single",Retargeting!$B$6:$B$53,"spread",Retargeting!$C$6:$C$53,6,Retargeting!$E$6:$E$53,40),"") -> 4.48
A65: B Distinct enemies touched per chain
A66: The AoE effect from single-target units.
B67: 20 enemies | C67: 12 enemies | D67: 6 enemies
A68: same | B68: =IFERROR(AVERAGEIFS(Retargeting!$J$6:$J$53,Retargeting!$A$6:$A$53,"single",Retargeting!$B$6:$B$53,"same",Retargeting!$C$6:$C$53,20,Retargeting!$E$6:$E$53,40),"") -> 1 | C68: =IFERROR(AVERAGEIFS(Retargeting!$J$6:$J$53,Retargeting!$A$6:$A$53,"single",Retargeting!$B$6:$B$53,"same",Retargeting!$C$6:$C$53,12,Retargeting!$E$6:$E$53,40),"") -> 1 | D68: =IFERROR(AVERAGEIFS(Retargeting!$J$6:$J$53,Retargeting!$A$6:$A$53,"single",Retargeting!$B$6:$B$53,"same",Retargeting!$C$6:$C$53,6,Retargeting!$E$6:$E$53,40),"") -> 1
A69: redirect | B69: =IFERROR(AVERAGEIFS(Retargeting!$J$6:$J$53,Retargeting!$A$6:$A$53,"single",Retargeting!$B$6:$B$53,"redirect",Retargeting!$C$6:$C$53,20,Retargeting!$E$6:$E$53,40),"") -> 2.48 | C69: =IFERROR(AVERAGEIFS(Retargeting!$J$6:$J$53,Retargeting!$A$6:$A$53,"single",Retargeting!$B$6:$B$53,"redirect",Retargeting!$C$6:$C$53,12,Retargeting!$E$6:$E$53,40),"") -> 2.07 | D69: =IFERROR(AVERAGEIFS(Retargeting!$J$6:$J$53,Retargeting!$A$6:$A$53,"single",Retargeting!$B$6:$B$53,"redirect",Retargeting!$C$6:$C$53,6,Retargeting!$E$6:$E$53,40),"") -> 1.77
A70: random | B70: =IFERROR(AVERAGEIFS(Retargeting!$J$6:$J$53,Retargeting!$A$6:$A$53,"single",Retargeting!$B$6:$B$53,"random",Retargeting!$C$6:$C$53,20,Retargeting!$E$6:$E$53,40),"") -> 4.68 | C70: =IFERROR(AVERAGEIFS(Retargeting!$J$6:$J$53,Retargeting!$A$6:$A$53,"single",Retargeting!$B$6:$B$53,"random",Retargeting!$C$6:$C$53,12,Retargeting!$E$6:$E$53,40),"") -> 3.53 | D70: =IFERROR(AVERAGEIFS(Retargeting!$J$6:$J$53,Retargeting!$A$6:$A$53,"single",Retargeting!$B$6:$B$53,"random",Retargeting!$C$6:$C$53,6,Retargeting!$E$6:$E$53,40),"") -> 2.55
A71: spread | B71: =IFERROR(AVERAGEIFS(Retargeting!$J$6:$J$53,Retargeting!$A$6:$A$53,"single",Retargeting!$B$6:$B$53,"spread",Retargeting!$C$6:$C$53,20,Retargeting!$E$6:$E$53,40),"") -> 4.6 | C71: =IFERROR(AVERAGEIFS(Retargeting!$J$6:$J$53,Retargeting!$A$6:$A$53,"single",Retargeting!$B$6:$B$53,"spread",Retargeting!$C$6:$C$53,12,Retargeting!$E$6:$E$53,40),"") -> 3.48 | D71: =IFERROR(AVERAGEIFS(Retargeting!$J$6:$J$53,Retargeting!$A$6:$A$53,"single",Retargeting!$B$6:$B$53,"spread",Retargeting!$C$6:$C$53,6,Retargeting!$E$6:$E$53,40),"") -> 2.35
A74: C Chains of five or more per fight
B76: 20 enemies | C76: 12 enemies | D76: 6 enemies
A77: same | B77: =IFERROR(AVERAGEIFS(Retargeting!$K$6:$K$53,Retargeting!$A$6:$A$53,"single",Retargeting!$B$6:$B$53,"same",Retargeting!$C$6:$C$53,20,Retargeting!$E$6:$E$53,40),"") -> 6.87 | C77: =IFERROR(AVERAGEIFS(Retargeting!$K$6:$K$53,Retargeting!$A$6:$A$53,"single",Retargeting!$B$6:$B$53,"same",Retargeting!$C$6:$C$53,12,Retargeting!$E$6:$E$53,40),"") -> 4.14 | D77: =IFERROR(AVERAGEIFS(Retargeting!$K$6:$K$53,Retargeting!$A$6:$A$53,"single",Retargeting!$B$6:$B$53,"same",Retargeting!$C$6:$C$53,6,Retargeting!$E$6:$E$53,40),"") -> 2.22
A78: redirect | B78: =IFERROR(AVERAGEIFS(Retargeting!$K$6:$K$53,Retargeting!$A$6:$A$53,"single",Retargeting!$B$6:$B$53,"redirect",Retargeting!$C$6:$C$53,20,Retargeting!$E$6:$E$53,40),"") -> 12.26 | C78: =IFERROR(AVERAGEIFS(Retargeting!$K$6:$K$53,Retargeting!$A$6:$A$53,"single",Retargeting!$B$6:$B$53,"redirect",Retargeting!$C$6:$C$53,12,Retargeting!$E$6:$E$53,40),"") -> 7.51 | D78: =IFERROR(AVERAGEIFS(Retargeting!$K$6:$K$53,Retargeting!$A$6:$A$53,"single",Retargeting!$B$6:$B$53,"redirect",Retargeting!$C$6:$C$53,6,Retargeting!$E$6:$E$53,40),"") -> 3.51
A79: random | B79: =IFERROR(AVERAGEIFS(Retargeting!$K$6:$K$53,Retargeting!$A$6:$A$53,"single",Retargeting!$B$6:$B$53,"random",Retargeting!$C$6:$C$53,20,Retargeting!$E$6:$E$53,40),"") -> 13.58 | C79: =IFERROR(AVERAGEIFS(Retargeting!$K$6:$K$53,Retargeting!$A$6:$A$53,"single",Retargeting!$B$6:$B$53,"random",Retargeting!$C$6:$C$53,12,Retargeting!$E$6:$E$53,40),"") -> 8 | D79: =IFERROR(AVERAGEIFS(Retargeting!$K$6:$K$53,Retargeting!$A$6:$A$53,"single",Retargeting!$B$6:$B$53,"random",Retargeting!$C$6:$C$53,6,Retargeting!$E$6:$E$53,40),"") -> 3.56
A80: spread | B80: =IFERROR(AVERAGEIFS(Retargeting!$K$6:$K$53,Retargeting!$A$6:$A$53,"single",Retargeting!$B$6:$B$53,"spread",Retargeting!$C$6:$C$53,20,Retargeting!$E$6:$E$53,40),"") -> 13.5 | C80: =IFERROR(AVERAGEIFS(Retargeting!$K$6:$K$53,Retargeting!$A$6:$A$53,"single",Retargeting!$B$6:$B$53,"spread",Retargeting!$C$6:$C$53,12,Retargeting!$E$6:$E$53,40),"") -> 7.89 | D80: =IFERROR(AVERAGEIFS(Retargeting!$K$6:$K$53,Retargeting!$A$6:$A$53,"single",Retargeting!$B$6:$B$53,"spread",Retargeting!$C$6:$C$53,6,Retargeting!$E$6:$E$53,40),"") -> 3.5
A83: D What the chains cost in screen time
A84: Seconds of follow-up animation per fight at 20 enemies. The right column is the budget that works.
B85: as full staged actions | C85: as quick strikes (0.30s)
...

Sheet Results
A1: team | B1: field | C1: pool | D1: harmony | E1: members | F1: win pct | G1: rounds | H1: actions | I1: breaks | J1: harmony triggers | K1: detonations | L1: damage taken | M1: peak on board | N1: fight minutes | O1: actions per round | P1: fights per session | Q1: pct of session
A2: aoe | B2: 3 | C2: 6 | D2: none | E2: 0 | F2: 100 | G2: 6.67 | H2: 30.4 | I2: 6.29 | J2: 0 | K2: 0 | L2: 79 | M2: 3 | N2: =H2*Parameters!$B$6/60 -> 0.78533333 | O2: =IF(G2=0,0,H2/G2) -> 4.5577211 | P2: =IF(N2=0,0,Parameters!$B$8/N2) -> 59.847199 | Q2: =N2/Parameters!$B$8 -> 0.01670922
A3: aoe | B3: 3 | C3: 6 | D3: cascade | E3: 2 | F3: 100 | G3: 6.28 | H3: 28.6 | I3: 6.29 | J3: 6.29 | K3: 0 | L3: 79 | M3: 3 | N3: =H3*Parameters!$B$6/60 -> 0.73883333 | O3: =IF(G3=0,0,H3/G3) -> 4.5541401 | P3: =IF(N3=0,0,Parameters!$B$8/N3) -> 63.613806 | Q3: =N3/Parameters!$B$8 -> 0.015719858
A4: aoe | B4: 3 | C4: 6 | D4: cascade | E4: 3 | F4: 100 | G4: 6.05 | H4: 26.9 | I4: 6.29 | J4: 12.58 | K4: 0 | L4: 78 | M4: 3 | N4: =H4*Parameters!$B$6/60 -> 0.69491667 | O4: =IF(G4=0,0,H4/G4) -> 4.446281 | P4: =IF(N4=0,0,Parameters!$B$8/N4) -> 67.634009 | Q4: =N4/Parameters!$B$8 -> 0.014785461
A5: aoe | B5: 3 | C5: 6 | D5: cascade | E5: 4 | F5: 100 | G5: 5.01 | H5: 23 | I5: 6.59 | J5: 19.78 | K5: 0 | L5: 72 | M5: 3 | N5: =H5*Parameters!$B$6/60 -> 0.59416667 | O5: =IF(G5=0,0,H5/G5) -> 4.5908184 | P5: =IF(N5=0,0,Parameters!$B$8/N5) -> 79.102384 | Q5: =N5/Parameters!$B$8 -> 0.012641844
A6: aoe | B6: 3 | C6: 6 | D6: break | E6: 2 | F6: 100 | G6: 6 | H6: 27 | I6: 8.2 | J6: 0 | K6: 0 | L6: 37 | M6: 3 | N6: =H6*Parameters!$B$6/60 -> 0.6975 | O6: =IF(G6=0,0,H6/G6) -> 4.5 | P6: =IF(N6=0,0,Parameters!$B$8/N6) -> 67.383513 | Q6: =N6/Parameters!$B$8 -> 0.014840426
A7: aoe | B7: 3 | C7: 6 | D7: break | E7: 3 | F7: 100 | G7: 5.99 | H7: 25.7 | I7: 8.39 | J7: 0 | K7: 0 | L7: 36 | M7: 3 | N7: =H7*Parameters!$B$6/60 -> 0.66391667 | O7: =IF(G7=0,0,H7/G7) -> 4.2904841 | P7: =IF(N7=0,0,Parameters!$B$8/N7) -> 70.792017 | Q7: =N7/Parameters!$B$8 -> 0.014125887
A8: aoe | B8: 3 | C8: 6 | D8: break | E8: 4 | F8: 100 | G8: 5.89 | H8: 25.4 | I8: 8.39 | J8: 0 | K8: 0 | L8: 36 | M8: 3 | N8: =H8*Parameters!$B$6/60 -> 0.65616667 | O8: =IF(G8=0,0,H8/G8) -> 4.3123939 | P8: =IF(N8=0,0,Parameters!$B$8/N8) -> 71.628143 | Q8: =N8/Parameters!$B$8 -> 0.013960993
A9: aoe | B9: 3 | C9: 6 | D9: detonation | E9: 2 | F9: 100 | G9: 3 | H9: 15 | I9: 5 | J9: 0 | K9: 3 | L9: 49 | M9: 3 | N9: =H9*Parameters!$B$6/60 -> 0.3875 | O9: =IF(G9=0,0,H9/G9) -> 5 | P9: =IF(N9=0,0,Parameters!$B$8/N9) -> 121.29032 | Q9: =N9/Parameters!$B$8 -> 0.0082446809
A10: aoe | B10: 3 | C10: 6 | D10: detonation | E10: 3 | F10: 100 | G10: 3 | H10: 14.9 | I10: 5 | J10: 0 | K10: 3 | L10: 48 | M10: 3 | N10: =H10*Parameters!$B$6/60 -> 0.38491667 | O10: =IF(G10=0,0,H10/G10) -> 4.9666667 | P10: =IF(N10=0,0,Parameters!$B$8/N10) -> 122.10435 | Q10: =N10/Parameters!$B$8 -> 0.0081897163
A11: aoe | B11: 3 | C11: 6 | D11: detonation | E11: 4 | F11: 100 | G11: 3 | H11: 13.5 | I11: 3 | J11: 0 | K11: 2 | L11: 46 | M11: 3 | N11: =H11*Parameters!$B$6/60 -> 0.34875 | O11: =IF(G11=0,0,H11/G11) -> 4.5 | P11: =IF(N11=0,0,Parameters!$B$8/N11) -> 134.76703 | Q11: =N11/Parameters!$B$8 -> 0.0074202128
A12: aoe | B12: 3 | C12: 12 | D12: none | E12: 0 | F12: 100 | G12: 9.54 | H12: 48.3 | I12: 13.6 | J12: 0 | K12: 0 | L12: 175 | M12: 3 | N12: =H12*Parameters!$B$6/60 -> 1.24775 | O12: =IF(G12=0,0,H12/G12) -> 5.0628931 | P12: =IF(N12=0,0,Parameters!$B$8/N12) -> 37.667802 | Q12: =N12/Parameters!$B$8 -> 0.026547872
A13: aoe | B13: 3 | C13: 12 | D13: cascade | E13: 2 | F13: 100 | G13: 9.23 | H13: 47.3 | I13: 12.75 | J13: 12.75 | K13: 0 | L13: 172 | M13: 3 | N13: =H13*Parameters!$B$6/60 -> 1.2219167 | O13: =IF(G13=0,0,H13/G13) -> 5.1245937 | P13: =IF(N13=0,0,Parameters!$B$8/N13) -> 38.464161 | Q13: =N13/Parameters!$B$8 -> 0.025998227
... A241: mixed | B241: 9 | C241: 20 | D241: detonation | E241: 4 | F241: 96.8 | G241: 7.32 | H241: 45.5 | I241: 7.23 | J241: 0 | K241: 3 | L241: 302 | M241: 9 | N241: =H241*Parameters!$B$6/60 -> 1.1754167 | O241: =IF(G241=0,0,H241/G241) -> 6.215847 | P241: =IF(N241=0,0,Parameters!$B$8/N241) -> 39.985821 | Q241: =N241/Parameters!$B$8 -> 0.025008865
